Workbook

Sheet Important Note
A2: All the input table should be cleared out when we click the submit button and these data should be updated in the consolidated database to fetch them when needed.

Sheet Input tabs for admin >>

Sheet Onboarding tab
B4: Table 1. Fund Onboarding table
B5: this is the input table and will consilated all the funds at the 2nd table we should have to see the current funds with their currency
B6: Fund Name | C6: Fund Currency
A7: input rows >> | B7: Fund 1 | C7: USD | D7: << example
A8: input rows >>
A9: input rows >>
A10: input rows >>
A11: input rows >>
B14: After we have the funds setup we can put the deals in which these funds are invested in
B16: Table 2. Deal or Investment Table
B17: this is the input table and will consilated all the funds at the 2nd table we should have to see the current funds with their currency
B18: Investment Name | C18: Fund Name | D18: Fund Ownership | E18: Deal Currency
A19: input rows >> | B19: Investment 1 | C19: Fund 1 | D19: 0.5 | E19: USD | F19: << example matching the the data we will be using
A20: input rows >> | B20: Investment 1 | C20: Fund 2 | D20: 0.5 | E20: USD | F20: << example matching the the data we will be using
A21: input rows >>
A22: input rows >>
A23: input rows >>

Sheet Quarterly Input Tab
B2: In the above section of page, should be what NAV and Debt MTM stands for and why these are important
B3: Instructions on how to update it ?
B5: Table 1. Nav & Debt MTM Input tab
B7: Selection table
A8: Important for quarter selection>> | B8: quarter dropdown for the quarter to update
C9: internal calculation | D9: internal calculation | E9: internal calculation | F9: manual input | G9: internal calculation | H9: internal calculation | I9: internal calculation
C10: Fund Ownership % | G10: NAV Amt
B11: Investment deal | C11: Fund 1 | D11: Fund 2 | E11: Fund 3 | F11: Total NAV @100% | G11: Fund 1 | H11: Fund 2 | I11: Fund 3
A12: input rows >> | B12: Investment 1 | C12: =INDEX('Ownerhsip %'!$C$6:$E$20,MATCH('Quarterly Input Tab'!$B12,'Ownerhsip %'!$B$6:$B$20,0),MATCH('Quarterly Input Tab'!C$11,'Ownerhsip %'!$C$5:$E$5,0)) -> 0.5 | D12: =INDEX('Ownerhsip %'!$C$6:$E$20,MATCH('Quarterly Input Tab'!$B12,'Ownerhsip %'!$B$6:$B$20,0),MATCH('Quarterly Input Tab'!D$11,'Ownerhsip %'!$C$5:$E$5,0)) -> 0.5 | E12: =INDEX('Ownerhsip %'!$C$6:$E$20,MATCH('Quarterly Input Tab'!$B12,'Ownerhsip %'!$B$6:$B$20,0),MATCH('Quarterly Input Tab'!E$11,'Ownerhsip %'!$C$5:$E$5,0)) -> 0 | F12: 1000000 | G12: =$F12*INDEX('Ownerhsip %'!$C$6:$E$20,MATCH($B12,'Ownerhsip %'!$B$6:$B$20,0),MATCH(G$11,'Ownerhsip %'!$C$5:$E$5,0)) -> 500000 | H12: =$F12*INDEX('Ownerhsip %'!$C$6:$E$20,MATCH($B12,'Ownerhsip %'!$B$6:$B$20,0),MATCH(H$11,'Ownerhsip %'!$C$5:$E$5,0)) -> 500000 | I12: =$F12*INDEX('Ownerhsip %'!$C$6:$E$20,MATCH($B12,'Ownerhsip %'!$B$6:$B$20,0),MATCH(I$11,'Ownerhsip %'!$C$5:$E$5,0)) -> 0
A13: input rows >> | B13: Investment 2 | C13: =INDEX('Ownerhsip %'!$C$6:$E$20,MATCH('Quarterly Input Tab'!$B13,'Ownerhsip %'!$B$6:$B$20,0),MATCH('Quarterly Input Tab'!C$11,'Ownerhsip %'!$C$5:$E$5,0)) -> 1 | D13: =INDEX('Ownerhsip %'!$C$6:$E$20,MATCH('Quarterly Input Tab'!$B13,'Ownerhsip %'!$B$6:$B$20,0),MATCH('Quarterly Input Tab'!D$11,'Ownerhsip %'!$C$5:$E$5,0)) -> 0 | E13: =INDEX('Ownerhsip %'!$C$6:$E$20,MATCH('Quarterly Input Tab'!$B13,'Ownerhsip %'!$B$6:$B$20,0),MATCH('Quarterly Input Tab'!E$11,'Ownerhsip %'!$C$5:$E$5,0)) -> 0 | F13: 200000 | G13: =$F13*INDEX('Ownerhsip %'!$C$6:$E$20,MATCH($B13,'Ownerhsip %'!$B$6:$B$20,0),MATCH(G$11,'Ownerhsip %'!$C$5:$E$5,0)) -> 200000 | H13: =$F13*INDEX('Ownerhsip %'!$C$6:$E$20,MATCH($B13,'Ownerhsip %'!$B$6:$B$20,0),MATCH(H$11,'Ownerhsip %'!$C$5:$E$5,0)) -> 0 | I13: =$F13*INDEX('Ownerhsip %'!$C$6:$E$20,MATCH($B13,'Ownerhsip %'!$B$6:$B$20,0),MATCH(I$11,'Ownerhsip %'!$C$5:$E$5,0)) -> 0
A14: input rows >> | B14: Investment 3 | C14: =INDEX('Ownerhsip %'!$C$6:$E$20,MATCH('Quarterly Input Tab'!$B14,'Ownerhsip %'!$B$6:$B$20,0),MATCH('Quarterly Input Tab'!C$11,'Ownerhsip %'!$C$5:$E$5,0)) -> 1 | D14: =INDEX('Ownerhsip %'!$C$6:$E$20,MATCH('Quarterly Input Tab'!$B14,'Ownerhsip %'!$B$6:$B$20,0),MATCH('Quarterly Input Tab'!D$11,'Ownerhsip %'!$C$5:$E$5,0)) -> 0 | E14: =INDEX('Ownerhsip %'!$C$6:$E$20,MATCH('Quarterly Input Tab'!$B14,'Ownerhsip %'!$B$6:$B$20,0),MATCH('Quarterly Input Tab'!E$11,'Ownerhsip %'!$C$5:$E$5,0)) -> 0 | F14: 350000 | G14: =$F14*INDEX('Ownerhsip %'!$C$6:$E$20,MATCH($B14,'Ownerhsip %'!$B$6:$B$20,0),MATCH(G$11,'Ownerhsip %'!$C$5:$E$5,0)) -> 350000 | H14: =$F14*INDEX('Ownerhsip %'!$C$6:$E$20,MATCH($B14,'Ownerhsip %'!$B$6:$B$20,0),MATCH(H$11,'Ownerhsip %'!$C$5:$E$5,0)) -> 0 | I14: =$F14*INDEX('Ownerhsip %'!$C$6:$E$20,MATCH($B14,'Ownerhsip %'!$B$6:$B$20,0),MATCH(I$11,'Ownerhsip %'!$C$5:$E$5,0)) -> 0
A15: input rows >> | B15: Investment 4 | C15: =INDEX('Ownerhsip %'!$C$6:$E$20,MATCH('Quarterly Input Tab'!$B15,'Ownerhsip %'!$B$6:$B$20,0),MATCH('Quarterly Input Tab'!C$11,'Ownerhsip %'!$C$5:$E$5,0)) -> 0 | D15: =INDEX('Ownerhsip %'!$C$6:$E$20,MATCH('Quarterly Input Tab'!$B15,'Ownerhsip %'!$B$6:$B$20,0),MATCH('Quarterly Input Tab'!D$11,'Ownerhsip %'!$C$5:$E$5,0)) -> 0.75 | E15: =INDEX('Ownerhsip %'!$C$6:$E$20,MATCH('Quarterly Input Tab'!$B15,'Ownerhsip %'!$B$6:$B$20,0),MATCH('Quarterly Input Tab'!E$11,'Ownerhsip %'!$C$5:$E$5,0)) -> 0.25 | F15: 985000 | G15: =$F15*INDEX('Ownerhsip %'!$C$6:$E$20,MATCH($B15,'Ownerhsip %'!$B$6:$B$20,0),MATCH(G$11,'Ownerhsip %'!$C$5:$E$5,0)) -> 0 | H15: =$F15*INDEX('Ownerhsip %'!$C$6:$E$20,MATCH($B15,'Ownerhsip %'!$B$6:$B$20,0),MATCH(H$11,'Ownerhsip %'!$C$5:$E$5,0)) -> 738750 | I15: =$F15*INDEX('Ownerhsip %'!$C$6:$E$20,MATCH($B15,'Ownerhsip %'!$B$6:$B$20,0),MATCH(I$11,'Ownerhsip %'!$C$5:$E$5,0)) -> 246250
A16: input rows >> | B16: Investment 5 | C16: =INDEX('Ownerhsip %'!$C$6:$E$20,MATCH('Quarterly Input Tab'!$B16,'Ownerhsip %'!$B$6:$B$20,0),MATCH('Quarterly Input Tab'!C$11,'Ownerhsip %'!$C$5:$E$5,0)) -> 0 | D16: =INDEX('Ownerhsip %'!$C$6:$E$20,MATCH('Quarterly Input Tab'!$B16,'Ownerhsip %'!$B$6:$B$20,0),MATCH('Quarterly Input Tab'!D$11,'Ownerhsip %'!$C$5:$E$5,0)) -> 0 | E16: =INDEX('Ownerhsip %'!$C$6:$E$20,MATCH('Quarterly Input Tab'!$B16,'Ownerhsip %'!$B$6:$B$20,0),MATCH('Quarterly Input Tab'!E$11,'Ownerhsip %'!$C$5:$E$5,0)) -> 1 | F16: 565000 | G16: =$F16*INDEX('Ownerhsip %'!$C$6:$E$20,MATCH($B16,'Ownerhsip %'!$B$6:$B$20,0),MATCH(G$11,'Ownerhsip %'!$C$5:$E$5,0)) -> 0 | H16: =$F16*INDEX('Ownerhsip %'!$C$6:$E$20,MATCH($B16,'Ownerhsip %'!$B$6:$B$20,0),MATCH(H$11,'Ownerhsip %'!$C$5:$E$5,0)) -> 0 | I16: =$F16*INDEX('Ownerhsip %'!$C$6:$E$20,MATCH($B16,'Ownerhsip %'!$B$6:$B$20,0),MATCH(I$11,'Ownerhsip %'!$C$5:$E$5,0)) -> 565000
A17: input rows >> | B17: Investment 6 | C17: =INDEX('Ownerhsip %'!$C$6:$E$20,MATCH('Quarterly Input Tab'!$B17,'Ownerhsip %'!$B$6:$B$20,0),MATCH('Quarterly Input Tab'!C$11,'Ownerhsip %'!$C$5:$E$5,0)) -> 0 | D17: =INDEX('Ownerhsip %'!$C$6:$E$20,MATCH('Quarterly Input Tab'!$B17,'Ownerhsip %'!$B$6:$B$20,0),MATCH('Quarterly Input Tab'!D$11,'Ownerhsip %'!$C$5:$E$5,0)) -> 0 | E17: =INDEX('Ownerhsip %'!$C$6:$E$20,MATCH('Quarterly Input Tab'!$B17,'Ownerhsip %'!$B$6:$B$20,0),MATCH('Quarterly Input Tab'!E$11,'Ownerhsip %'!$C$5:$E$5,0)) -> 1 | F17: 5500000 | G17: =$F17*INDEX('Ownerhsip %'!$C$6:$E$20,MATCH($B17,'Ownerhsip %'!$B$6:$B$20,0),MATCH(G$11,'Ownerhsip %'!$C$5:$E$5,0)) -> 0 | H17: =$F17*INDEX('Ownerhsip %'!$C$6:$E$20,MATCH($B17,'Ownerhsip %'!$B$6:$B$20,0),MATCH(H$11,'Ownerhsip %'!$C$5:$E$5,0)) -> 0 | I17: =$F17*INDEX('Ownerhsip %'!$C$6:$E$20,MATCH($B17,'Ownerhsip %'!$B$6:$B$20,0),MATCH(I$11,'Ownerhsip %'!$C$5:$E$5,0)) -> 5500000
A18: input rows >> | B18: Investment 7 | C18: =INDEX('Ownerhsip %'!$C$6:$E$20,MATCH('Quarterly Input Tab'!$B18,'Ownerhsip %'!$B$6:$B$20,0),MATCH('Quarterly Input Tab'!C$11,'Ownerhsip %'!$C$5:$E$5,0)) -> 0 | D18: =INDEX('Ownerhsip %'!$C$6:$E$20,MATCH('Quarterly Input Tab'!$B18,'Ownerhsip %'!$B$6:$B$20,0),MATCH('Quarterly Input Tab'!D$11,'Ownerhsip %'!$C$5:$E$5,0)) -> 1 | E18: =INDEX('Ownerhsip %'!$C$6:$E$20,MATCH('Quarterly Input Tab'!$B18,'Ownerhsip %'!$B$6:$B$20,0),MATCH('Quarterly Input Tab'!E$11,'Ownerhsip %'!$C$5:$E$5,0)) -> 0 | F18: 120000 | G18: =$F18*INDEX('Ownerhsip %'!$C$6:$E$20,MATCH($B18,'Ownerhsip %'!$B$6:$B$20,0),MATCH(G$11,'Ownerhsip %'!$C$5:$E$5,0)) -> 0 | H18: =$F18*INDEX('Ownerhsip %'!$C$6:$E$20,MATCH($B18,'Ownerhsip %'!$B$6:$B$20,0),MATCH(H$11,'Ownerhsip %'!$C$5:$E$5,0)) -> 120000 | I18: =$F18*INDEX('Ownerhsip %'!$C$6:$E$20,MATCH($B18,'Ownerhsip %'!$B$6:$B$20,0),MATCH(I$11,'Ownerhsip %'!$C$5:$E$5,0)) -> 0
A19: input rows >> | B19: Investment 8 | C19: =INDEX('Ownerhsip %'!$C$6:$E$20,MATCH('Quarterly Input Tab'!$B19,'Ownerhsip %'!$B$6:$B$20,0),MATCH('Quarterly Input Tab'!C$11,'Ownerhsip %'!$C$5:$E$5,0)) -> 0 | D19: =INDEX('Ownerhsip %'!$C$6:$E$20,MATCH('Quarterly Input Tab'!$B19,'Ownerhsip %'!$B$6:$B$20,0),MATCH('Quarterly Input Tab'!D$11,'Ownerhsip %'!$C$5:$E$5,0)) -> 1 | E19: =INDEX('Ownerhsip %'!$C$6:$E$20,MATCH('Quarterly Input Tab'!$B19,'Ownerhsip %'!$B$6:$B$20,0),MATCH('Quarterly Input Tab'!E$11,'Ownerhsip %'!$C$5:$E$5,0)) -> 0 | F19: 95000 | G19: =$F19*INDEX('Ownerhsip %'!$C$6:$E$20,MATCH($B19,'Ownerhsip %'!$B$6:$B$20,0),MATCH(G$11,'Ownerhsip %'!$C$5:$E$5,0)) -> 0 | H19: =$F19*INDEX('Ownerhsip %'!$C$6:$E$20,MATCH($B19,'Ownerhsip %'!$B$6:$B$20,0),MATCH(H$11,'Ownerhsip %'!$C$5:$E$5,0)) -> 95000 | I19: =$F19*INDEX('Ownerhsip %'!$C$6:$E$20,MATCH($B19,'Ownerhsip %'!$B$6:$B$20,0),MATCH(I$11,'Ownerhsip %'!$C$5:$E$5,0)) -> 0
A20: input rows >> | B20: Investment 9 | C20: =INDEX('Ownerhsip %'!$C$6:$E$20,MATCH('Quarterly Input Tab'!$B20,'Ownerhsip %'!$B$6:$B$20,0),MATCH('Quarterly Input Tab'!C$11,'Ownerhsip %'!$C$5:$E$5,0)) -> 0 | D20: =INDEX('Ownerhsip %'!$C$6:$E$20,MATCH('Quarterly Input Tab'!$B20,'Ownerhsip %'!$B$6:$B$20,0),MATCH('Quarterly Input Tab'!D$11,'Ownerhsip %'!$C$5:$E$5,0)) -> 1 | E20: =INDEX('Ownerhsip %'!$C$6:$E$20,MATCH('Quarterly Input Tab'!$B20,'Ownerhsip %'!$B$6:$B$20,0),MATCH('Quarterly Input Tab'!E$11,'Ownerhsip %'!$C$5:$E$5,0)) -> 0 | F20: 4669566 | G20: =$F20*INDEX('Ownerhsip %'!$C$6:$E$20,MATCH($B20,'Ownerhsip %'!$B$6:$B$20,0),MATCH(G$11,'Ownerhsip %'!$C$5:$E$5,0)) -> 0 | H20: =$F20*INDEX('Ownerhsip %'!$C$6:$E$20,MATCH($B20,'Ownerhsip %'!$B$6:$B$20,0),MATCH(H$11,'Ownerhsip %'!$C$5:$E$5,0)) -> 4669566 | I20: =$F20*INDEX('Ownerhsip %'!$C$6:$E$20,MATCH($B20,'Ownerhsip %'!$B$6:$B$20,0),MATCH(I$11,'Ownerhsip %'!$C$5:$E$5,0)) -> 0
A21: input rows >> | B21: Investment 10 | C21: =INDEX('Ownerhsip %'!$C$6:$E$20,MATCH('Quarterly Input Tab'!$B21,'Ownerhsip %'!$B$6:$B$20,0),MATCH('Quarterly Input Tab'!C$11,'Ownerhsip %'!$C$5:$E$5,0)) -> 0 | D21: =INDEX('Ownerhsip %'!$C$6:$E$20,MATCH('Quarterly Input Tab'!$B21,'Ownerhsip %'!$B$6:$B$20,0),MATCH('Quarterly Input Tab'!D$11,'Ownerhsip %'!$C$5:$E$5,0)) -> 1 | E21: =INDEX('Ownerhsip %'!$C$6:$E$20,MATCH('Quarterly Input Tab'!$B21,'Ownerhsip %'!$B$6:$B$20,0),MATCH('Quarterly Input Tab'!E$11,'Ownerhsip %'!$C$5:$E$5,0)) -> 0 | F21: 4748844 | G21: =$F21*INDEX('Ownerhsip %'!$C$6:$E$20,MATCH($B21,'Ownerhsip %'!$B$6:$B$20,0),MATCH(G$11,'Ownerhsip %'!$C$5:$E$5,0)) -> 0 | H21: =$F21*INDEX('Ownerhsip %'!$C$6:$E$20,MATCH($B21,'Ownerhsip %'!$B$6:$B$20,0),MATCH(H$11,'Ownerhsip %'!$C$5:$E$5,0)) -> 4748844 | I21: =$F21*INDEX('Ownerhsip %'!$C$6:$E$20,MATCH($B21,'Ownerhsip %'!$B$6:$B$20,0),MATCH(I$11,'Ownerhsip %'!$C$5:$E$5,0)) -> 0
A22: input rows >> | B22: Investment 11 | C22: =INDEX('Ownerhsip %'!$C$6:$E$20,MATCH('Quarterly Input Tab'!$B22,'Ownerhsip %'!$B$6:$B$20,0),MATCH('Quarterly Input Tab'!C$11,'Ownerhsip %'!$C$5:$E$5,0)) -> 0.5 | D22: =INDEX('Ownerhsip %'!$C$6:$E$20,MATCH('Quarterly Input Tab'!$B22,'Ownerhsip %'!$B$6:$B$20,0),MATCH('Quarterly Input Tab'!D$11,'Ownerhsip %'!$C$5:$E$5,0)) -> 0 | E22: =INDEX('Ownerhsip %'!$C$6:$E$20,MATCH('Quarterly Input Tab'!$B22,'Ownerhsip %'!$B$6:$B$20,0),MATCH('Quarterly Input Tab'!E$11,'Ownerhsip %'!$C$5:$E$5,0)) -> 0.5 | F22: 2323111 | G22: =$F22*INDEX('Ownerhsip %'!$C$6:$E$20,MATCH($B22,'Ownerhsip %'!$B$6:$B$20,0),MATCH(G$11,'Ownerhsip %'!$C$5:$E$5,0)) -> 1161555.5 | H22: =$F22*INDEX('Ownerhsip %'!$C$6:$E$20,MATCH($B22,'Ownerhsip %'!$B$6:$B$20,0),MATCH(H$11,'Ownerhsip %'!$C$5:$E$5,0)) -> 0 | I22: =$F22*INDEX('Ownerhsip %'!$C$6:$E$20,MATCH($B22,'Ownerhsip %'!$B$6:$B$20,0),MATCH(I$11,'Ownerhsip %'!$C$5:$E$5,0)) -> 1161555.5
A23: input rows >> | B23: Investment 12 | C23: =INDEX('Ownerhsip %'!$C$6:$E$20,MATCH('Quarterly Input Tab'!$B23,'Ownerhsip %'!$B$6:$B$20,0),MATCH('Quarterly Input Tab'!C$11,'Ownerhsip %'!$C$5:$E$5,0)) -> 1 | D23: =INDEX('Ownerhsip %'!$C$6:$E$20,MATCH('Quarterly Input Tab'!$B23,'Ownerhsip %'!$B$6:$B$20,0),MATCH('Quarterly Input Tab'!D$11,'Ownerhsip %'!$C$5:$E$5,0)) -> 0 | E23: =INDEX('Ownerhsip %'!$C$6:$E$20,MATCH('Quarterly Input Tab'!$B23,'Ownerhsip %'!$B$6:$B$20,0),MATCH('Quarterly Input Tab'!E$11,'Ownerhsip %'!$C$5:$E$5,0)) -> 0 | F23: 674602 | G23: =$F23*INDEX('Ownerhsip %'!$C$6:$E$20,MATCH($B23,'Ownerhsip %'!$B$6:$B$20,0),MATCH(G$11,'Ownerhsip %'!$C$5:$E$5,0)) -> 674602 | H23: =$F23*INDEX('Ownerhsip %'!$C$6:$E$20,MATCH($B23,'Ownerhsip %'!$B$6:$B$20,0),MATCH(H$11,'Ownerhsip %'!$C$5:$E$5,0)) -> 0 | I23: =$F23*INDEX('Ownerhsip %'!$C$6:$E$20,MATCH($B23,'Ownerhsip %'!$B$6:$B$20,0),MATCH(I$11,'Ownerhsip %'!$C$5:$E$5,0)) -> 0
... A26: input rows >> | B26: Investment 15 | C26: =INDEX('Ownerhsip %'!$C$6:$E$20,MATCH('Quarterly Input Tab'!$B26,'Ownerhsip %'!$B$6:$B$20,0),MATCH('Quarterly Input Tab'!C$11,'Ownerhsip %'!$C$5:$E$5,0)) -> 0 | D26: =INDEX('Ownerhsip %'!$C$6:$E$20,MATCH('Quarterly Input Tab'!$B26,'Ownerhsip %'!$B$6:$B$20,0),MATCH('Quarterly Input Tab'!D$11,'Ownerhsip %'!$C$5:$E$5,0)) -> 0 | E26: =INDEX('Ownerhsip %'!$C$6:$E$20,MATCH('Quarterly Input Tab'!$B26,'Ownerhsip %'!$B$6:$B$20,0),MATCH('Quarterly Input Tab'!E$11,'Ownerhsip %'!$C$5:$E$5,0)) -> 1 | F26: 3097469 | G26: =$F26*INDEX('Ownerhsip %'!$C$6:$E$20,MATCH($B26,'Ownerhsip %'!$B$6:$B$20,0),MATCH(G$11,'Ownerhsip %'!$C$5:$E$5,0)) -> 0 | H26: =$F26*INDEX('Ownerhsip %'!$C$6:$E$20,MATCH($B26,'Ownerhsip %'!$B$6:$B$20,0),MATCH(H$11,'Ownerhsip %'!$C$5:$E$5,0)) -> 0 | I26: =$F26*INDEX('Ownerhsip %'!$C$6:$E$20,MATCH($B26,'Ownerhsip %'!$B$6:$B$20,0),MATCH(I$11,'Ownerhsip %'!$C$5:$E$5,0)) -> 3097469
A27: The above table after clicking on a submitted botton should clean this up and save it in a database which is consolidated for the below table
A31: need a consolidated table with a drap down option to select the nav and debt mtm for the selected quarter.
A32: look similar to the above table | B32: Investment deal | C32: Fund 1 | D32: Fund 2 | E32: Fund 3 | F32: Total NAV @100% | G32: Fund 1 | H32: Fund 2 | I32: Fund 3
B33: Investment 1 | C33: =INDEX('Ownerhsip %'!$C$6:$E$20,MATCH('Quarterly Input Tab'!$B33,'Ownerhsip %'!$B$6:$B$20,0),MATCH('Quarterly Input Tab'!C$11,'Ownerhsip %'!$C$5:$E$5,0)) -> 0.5 | D33: =INDEX('Ownerhsip %'!$C$6:$E$20,MATCH('Quarterly Input Tab'!$B33,'Ownerhsip %'!$B$6:$B$20,0),MATCH('Quarterly Input Tab'!D$11,'Ownerhsip %'!$C$5:$E$5,0)) -> 0.5 | E33: =INDEX('Ownerhsip %'!$C$6:$E$20,MATCH('Quarterly Input Tab'!$B33,'Ownerhsip %'!$B$6:$B$20,0),MATCH('Quarterly Input Tab'!E$11,'Ownerhsip %'!$C$5:$E$5,0)) -> 0 | F33: 1000000 | G33: =$F33*INDEX('Ownerhsip %'!$C$6:$E$20,MATCH($B33,'Ownerhsip %'!$B$6:$B$20,0),MATCH(G$11,'Ownerhsip %'!$C$5:$E$5,0)) -> 500000 | H33: =$F33*INDEX('Ownerhsip %'!$C$6:$E$20,MATCH($B33,'Ownerhsip %'!$B$6:$B$20,0),MATCH(H$11,'Ownerhsip %'!$C$5:$E$5,0)) -> 500000 | I33: =$F33*INDEX('Ownerhsip %'!$C$6:$E$20,MATCH($B33,'Ownerhsip %'!$B$6:$B$20,0),MATCH(I$11,'Ownerhsip %'!$C$5:$E$5,0)) -> 0
B34: Investment 2 | C34: =INDEX('Ownerhsip %'!$C$6:$E$20,MATCH('Quarterly Input Tab'!$B34,'Ownerhsip %'!$B$6:$B$20,0),MATCH('Quarterly Input Tab'!C$11,'Ownerhsip %'!$C$5:$E$5,0)) -> 1 | D34: =INDEX('Ownerhsip %'!$C$6:$E$20,MATCH('Quarterly Input Tab'!$B34,'Ownerhsip %'!$B$6:$B$20,0),MATCH('Quarterly Input Tab'!D$11,'Ownerhsip %'!$C$5:$E$5,0)) -> 0 | E34: =INDEX('Ownerhsip %'!$C$6:$E$20,MATCH('Quarterly Input Tab'!$B34,'Ownerhsip %'!$B$6:$B$20,0),MATCH('Quarterly Input Tab'!E$11,'Ownerhsip %'!$C$5:$E$5,0)) -> 0 | F34: 200000 | G34: =$F34*INDEX('Ownerhsip %'!$C$6:$E$20,MATCH($B34,'Ownerhsip %'!$B$6:$B$20,0),MATCH(G$11,'Ownerhsip %'!$C$5:$E$5,0)) -> 200000 | H34: =$F34*INDEX('Ownerhsip %'!$C$6:$E$20,MATCH($B34,'Ownerhsip %'!$B$6:$B$20,0),MATCH(H$11,'Ownerhsip %'!$C$5:$E$5,0)) -> 0 | I34: =$F34*INDEX('Ownerhsip %'!$C$6:$E$20,MATCH($B34,'Ownerhsip %'!$B$6:$B$20,0),MATCH(I$11,'Ownerhsip %'!$C$5:$E$5,0)) -> 0
B35: Investment 3 | C35: =INDEX('Ownerhsip %'!$C$6:$E$20,MATCH('Quarterly Input Tab'!$B35,'Ownerhsip %'!$B$6:$B$20,0),MATCH('Quarterly Input Tab'!C$11,'Ownerhsip %'!$C$5:$E$5,0)) -> 1 | D35: =INDEX('Ownerhsip %'!$C$6:$E$20,MATCH('Quarterly Input Tab'!$B35,'Ownerhsip %'!$B$6:$B$20,0),MATCH('Quarterly Input Tab'!D$11,'Ownerhsip %'!$C$5:$E$5,0)) -> 0 | E35: =INDEX('Ownerhsip %'!$C$6:$E$20,MATCH('Quarterly Input Tab'!$B35,'Ownerhsip %'!$B$6:$B$20,0),MATCH('Quarterly Input Tab'!E$11,'Ownerhsip %'!$C$5:$E$5,0)) -> 0 | F35: 350000 | G35: =$F35*INDEX('Ownerhsip %'!$C$6:$E$20,MATCH($B35,'Ownerhsip %'!$B$6:$B$20,0),MATCH(G$11,'Ownerhsip %'!$C$5:$E$5,0)) -> 350000 | H35: =$F35*INDEX('Ownerhsip %'!$C$6:$E$20,MATCH($B35,'Ownerhsip %'!$B$6:$B$20,0),MATCH(H$11,'Ownerhsip %'!$C$5:$E$5,0)) -> 0 | I35: =$F35*INDEX('Ownerhsip %'!$C$6:$E$20,MATCH($B35,'Ownerhsip %'!$B$6:$B$20,0),MATCH(I$11,'Ownerhsip %'!$C$5:$E$5,0)) -> 0
B36: Investment 4 | C36: =INDEX('Ownerhsip %'!$C$6:$E$20,MATCH('Quarterly Input Tab'!$B36,'Ownerhsip %'!$B$6:$B$20,0),MATCH('Quarterly Input Tab'!C$11,'Ownerhsip %'!$C$5:$E$5,0)) -> 0 | D36: =INDEX('Ownerhsip %'!$C$6:$E$20,MATCH('Quarterly Input Tab'!$B36,'Ownerhsip %'!$B$6:$B$20,0),MATCH('Quarterly Input Tab'!D$11,'Ownerhsip %'!$C$5:$E$5,0)) -> 0.75 | E36: =INDEX('Ownerhsip %'!$C$6:$E$20,MATCH('Quarterly Input Tab'!$B36,'Ownerhsip %'!$B$6:$B$20,0),MATCH('Quarterly Input Tab'!E$11,'Ownerhsip %'!$C$5:$E$5,0)) -> 0.25 | F36: 985000 | G36: =$F36*INDEX('Ownerhsip %'!$C$6:$E$20,MATCH($B36,'Ownerhsip %'!$B$6:$B$20,0),MATCH(G$11,'Ownerhsip %'!$C$5:$E$5,0)) -> 0 | H36: =$F36*INDEX('Ownerhsip %'!$C$6:$E$20,MATCH($B36,'Ownerhsip %'!$B$6:$B$20,0),MATCH(H$11,'Ownerhsip %'!$C$5:$E$5,0)) -> 738750 | I36: =$F36*INDEX('Ownerhsip %'!$C$6:$E$20,MATCH($B36,'Ownerhsip %'!$B$6:$B$20,0),MATCH(I$11,'Ownerhsip %'!$C$5:$E$5,0)) -> 246250
B37: Investment 5 | C37: =INDEX('Ownerhsip %'!$C$6:$E$20,MATCH('Quarterly Input Tab'!$B37,'Ownerhsip %'!$B$6:$B$20,0),MATCH('Quarterly Input Tab'!C$11,'Ownerhsip %'!$C$5:$E$5,0)) -> 0 | D37: =INDEX('Ownerhsip %'!$C$6:$E$20,MATCH('Quarterly Input Tab'!$B37,'Ownerhsip %'!$B$6:$B$20,0),MATCH('Quarterly Input Tab'!D$11,'Ownerhsip %'!$C$5:$E$5,0)) -> 0 | E37: =INDEX('Ownerhsip %'!$C$6:$E$20,MATCH('Quarterly Input Tab'!$B37,'Ownerhsip %'!$B$6:$B$20,0),MATCH('Quarterly Input Tab'!E$11,'Ownerhsip %'!$C$5:$E$5,0)) -> 1 | F37: 565000 | G37: =$F37*INDEX('Ownerhsip %'!$C$6:$E$20,MATCH($B37,'Ownerhsip %'!$B$6:$B$20,0),MATCH(G$11,'Ownerhsip %'!$C$5:$E$5,0)) -> 0 | H37: =$F37*INDEX('Ownerhsip %'!$C$6:$E$20,MATCH($B37,'Ownerhsip %'!$B$6:$B$20,0),MATCH(H$11,'Ownerhsip %'!$C$5:$E$5,0)) -> 0 | I37: =$F37*INDEX('Ownerhsip %'!$C$6:$E$20,MATCH($B37,'Ownerhsip %'!$B$6:$B$20,0),MATCH(I$11,'Ownerhsip %'!$C$5:$E$5,0)) -> 565000
B38: Investment 6 | C38: =INDEX('Ownerhsip %'!$C$6:$E$20,MATCH('Quarterly Input Tab'!$B38,'Ownerhsip %'!$B$6:$B$20,0),MATCH('Quarterly Input Tab'!C$11,'Ownerhsip %'!$C$5:$E$5,0)) -> 0 | D38: =INDEX('Ownerhsip %'!$C$6:$E$20,MATCH('Quarterly Input Tab'!$B38,'Ownerhsip %'!$B$6:$B$20,0),MATCH('Quarterly Input Tab'!D$11,'Ownerhsip %'!$C$5:$E$5,0)) -> 0 | E38: =INDEX('Ownerhsip %'!$C$6:$E$20,MATCH('Quarterly Input Tab'!$B38,'Ownerhsip %'!$B$6:$B$20,0),MATCH('Quarterly Input Tab'!E$11,'Ownerhsip %'!$C$5:$E$5,0)) -> 1 | F38: 5500000 | G38: =$F38*INDEX('Ownerhsip %'!$C$6:$E$20,MATCH($B38,'Ownerhsip %'!$B$6:$B$20,0),MATCH(G$11,'Ownerhsip %'!$C$5:$E$5,0)) -> 0 | H38: =$F38*INDEX('Ownerhsip %'!$C$6:$E$20,MATCH($B38,'Ownerhsip %'!$B$6:$B$20,0),MATCH(H$11,'Ownerhsip %'!$C$5:$E$5,0)) -> 0 | I38: =$F38*INDEX('Ownerhsip %'!$C$6:$E$20,MATCH($B38,'Ownerhsip %'!$B$6:$B$20,0),MATCH(I$11,'Ownerhsip %'!$C$5:$E$5,0)) -> 5500000
B39: Investment 7 | C39: =INDEX('Ownerhsip %'!$C$6:$E$20,MATCH('Quarterly Input Tab'!$B39,'Ownerhsip %'!$B$6:$B$20,0),MATCH('Quarterly Input Tab'!C$11,'Ownerhsip %'!$C$5:$E$5,0)) -> 0 | D39: =INDEX('Ownerhsip %'!$C$6:$E$20,MATCH('Quarterly Input Tab'!$B39,'Ownerhsip %'!$B$6:$B$20,0),MATCH('Quarterly Input Tab'!D$11,'Ownerhsip %'!$C$5:$E$5,0)) -> 1 | E39: =INDEX('Ownerhsip %'!$C$6:$E$20,MATCH('Quarterly Input Tab'!$B39,'Ownerhsip %'!$B$6:$B$20,0),MATCH('Quarterly Input Tab'!E$11,'Ownerhsip %'!$C$5:$E$5,0)) -> 0 | F39: 120000 | G39: =$F39*INDEX('Ownerhsip %'!$C$6:$E$20,MATCH($B39,'Ownerhsip %'!$B$6:$B$20,0),MATCH(G$11,'Ownerhsip %'!$C$5:$E$5,0)) -> 0 | H39: =$F39*INDEX('Ownerhsip %'!$C$6:$E$20,MATCH($B39,'Ownerhsip %'!$B$6:$B$20,0),MATCH(H$11,'Ownerhsip %'!$C$5:$E$5,0)) -> 120000 | I39: =$F39*INDEX('Ownerhsip %'!$C$6:$E$20,MATCH($B39,'Ownerhsip %'!$B$6:$B$20,0),MATCH(I$11,'Ownerhsip %'!$C$5:$E$5,0)) -> 0
B40: Investment 8 | C40: =INDEX('Ownerhsip %'!$C$6:$E$20,MATCH('Quarterly Input Tab'!$B40,'Ownerhsip %'!$B$6:$B$20,0),MATCH('Quarterly Input Tab'!C$11,'Ownerhsip %'!$C$5:$E$5,0)) -> 0 | D40: =INDEX('Ownerhsip %'!$C$6:$E$20,MATCH('Quarterly Input Tab'!$B40,'Ownerhsip %'!$B$6:$B$20,0),MATCH('Quarterly Input Tab'!D$11,'Ownerhsip %'!$C$5:$E$5,0)) -> 1 | E40: =INDEX('Ownerhsip %'!$C$6:$E$20,MATCH('Quarterly Input Tab'!$B40,'Ownerhsip %'!$B$6:$B$20,0),MATCH('Quarterly Input Tab'!E$11,'Ownerhsip %'!$C$5:$E$5,0)) -> 0 | F40: 95000 | G40: =$F40*INDEX('Ownerhsip %'!$C$6:$E$20,MATCH($B40,'Ownerhsip %'!$B$6:$B$20,0),MATCH(G$11,'Ownerhsip %'!$C$5:$E$5,0)) -> 0 | H40: =$F40*INDEX('Ownerhsip %'!$C$6:$E$20,MATCH($B40,'Ownerhsip %'!$B$6:$B$20,0),MATCH(H$11,'Ownerhsip %'!$C$5:$E$5,0)) -> 95000 | I40: =$F40*INDEX('Ownerhsip %'!$C$6:$E$20,MATCH($B40,'Ownerhsip %'!$B$6:$B$20,0),MATCH(I$11,'Ownerhsip %'!$C$5:$E$5,0)) -> 0
B41: Investment 9 | C41: =INDEX('Ownerhsip %'!$C$6:$E$20,MATCH('Quarterly Input Tab'!$B41,'Ownerhsip %'!$B$6:$B$20,0),MATCH('Quarterly Input Tab'!C$11,'Ownerhsip %'!$C$5:$E$5,0)) -> 0 | D41: =INDEX('Ownerhsip %'!$C$6:$E$20,MATCH('Quarterly Input Tab'!$B41,'Ownerhsip %'!$B$6:$B$20,0),MATCH('Quarterly Input Tab'!D$11,'Ownerhsip %'!$C$5:$E$5,0)) -> 1 | E41: =INDEX('Ownerhsip %'!$C$6:$E$20,MATCH('Quarterly Input Tab'!$B41,'Ownerhsip %'!$B$6:$B$20,0),MATCH('Quarterly Input Tab'!E$11,'Ownerhsip %'!$C$5:$E$5,0)) -> 0 | F41: 4669566 | G41: =$F41*INDEX('Ownerhsip %'!$C$6:$E$20,MATCH($B41,'Ownerhsip %'!$B$6:$B$20,0),MATCH(G$11,'Ownerhsip %'!$C$5:$E$5,0)) -> 0 | H41: =$F41*INDEX('Ownerhsip %'!$C$6:$E$20,MATCH($B41,'Ownerhsip %'!$B$6:$B$20,0),MATCH(H$11,'Ownerhsip %'!$C$5:$E$5,0)) -> 4669566 | I41: =$F41*INDEX('Ownerhsip %'!$C$6:$E$20,MATCH($B41,'Ownerhsip %'!$B$6:$B$20,0),MATCH(I$11,'Ownerhsip %'!$C$5:$E$5,0)) -> 0
B42: Investment 10 | C42: =INDEX('Ownerhsip %'!$C$6:$E$20,MATCH('Quarterly Input Tab'!$B42,'Ownerhsip %'!$B$6:$B$20,0),MATCH('Quarterly Input Tab'!C$11,'Ownerhsip %'!$C$5:$E$5,0)) -> 0 | D42: =INDEX('Ownerhsip %'!$C$6:$E$20,MATCH('Quarterly Input Tab'!$B42,'Ownerhsip %'!$B$6:$B$20,0),MATCH('Quarterly Input Tab'!D$11,'Ownerhsip %'!$C$5:$E$5,0)) -> 1 | E42: =INDEX('Ownerhsip %'!$C$6:$E$20,MATCH('Quarterly Input Tab'!$B42,'Ownerhsip %'!$B$6:$B$20,0),MATCH('Quarterly Input Tab'!E$11,'Ownerhsip %'!$C$5:$E$5,0)) -> 0 | F42: 4748844 | G42: =$F42*INDEX('Ownerhsip %'!$C$6:$E$20,MATCH($B42,'Ownerhsip %'!$B$6:$B$20,0),MATCH(G$11,'Ownerhsip %'!$C$5:$E$5,0)) -> 0 | H42: =$F42*INDEX('Ownerhsip %'!$C$6:$E$20,MATCH($B42,'Ownerhsip %'!$B$6:$B$20,0),MATCH(H$11,'Ownerhsip %'!$C$5:$E$5,0)) -> 4748844 | I42: =$F42*INDEX('Ownerhsip %'!$C$6:$E$20,MATCH($B42,'Ownerhsip %'!$B$6:$B$20,0),MATCH(I$11,'Ownerhsip %'!$C$5:$E$5,0)) -> 0
B43: Investment 11 | C43: =INDEX('Ownerhsip %'!$C$6:$E$20,MATCH('Quarterly Input Tab'!$B43,'Ownerhsip %'!$B$6:$B$20,0),MATCH('Quarterly Input Tab'!C$11,'Ownerhsip %'!$C$5:$E$5,0)) -> 0.5 | D43: =INDEX('Ownerhsip %'!$C$6:$E$20,MATCH('Quarterly Input Tab'!$B43,'Ownerhsip %'!$B$6:$B$20,0),MATCH('Quarterly Input Tab'!D$11,'Ownerhsip %'!$C$5:$E$5,0)) -> 0 | E43: =INDEX('Ownerhsip %'!$C$6:$E$20,MATCH('Quarterly Input Tab'!$B43,'Ownerhsip %'!$B$6:$B$20,0),MATCH('Quarterly Input Tab'!E$11,'Ownerhsip %'!$C$5:$E$5,0)) -> 0.5 | F43: 2323111 | G43: =$F43*INDEX('Ownerhsip %'!$C$6:$E$20,MATCH($B43,'Ownerhsip %'!$B$6:$B$20,0),MATCH(G$11,'Ownerhsip %'!$C$5:$E$5,0)) -> 1161555.5 | H43: =$F43*INDEX('Ownerhsip %'!$C$6:$E$20,MATCH($B43,'Ownerhsip %'!$B$6:$B$20,0),MATCH(H$11,'Ownerhsip %'!$C$5:$E$5,0)) -> 0 | I43: =$F43*INDEX('Ownerhsip %'!$C$6:$E$20,MATCH($B43,'Ownerhsip %'!$B$6:$B$20,0),MATCH(I$11,'Ownerhsip %'!$C$5:$E$5,0)) -> 1161555.5
B44: Investment 12 | C44: =INDEX('Ownerhsip %'!$C$6:$E$20,MATCH('Quarterly Input Tab'!$B44,'Ownerhsip %'!$B$6:$B$20,0),MATCH('Quarterly Input Tab'!C$11,'Ownerhsip %'!$C$5:$E$5,0)) -> 1 | D44: =INDEX('Ownerhsip %'!$C$6:$E$20,MATCH('Quarterly Input Tab'!$B44,'Ownerhsip %'!$B$6:$B$20,0),MATCH('Quarterly Input Tab'!D$11,'Ownerhsip %'!$C$5:$E$5,0)) -> 0 | E44: =INDEX('Ownerhsip %'!$C$6:$E$20,MATCH('Quarterly Input Tab'!$B44,'Ownerhsip %'!$B$6:$B$20,0),MATCH('Quarterly Input Tab'!E$11,'Ownerhsip %'!$C$5:$E$5,0)) -> 0 | F44: 674602 | G44: =$F44*INDEX('Ownerhsip %'!$C$6:$E$20,MATCH($B44,'Ownerhsip %'!$B$6:$B$20,0),MATCH(G$11,'Ownerhsip %'!$C$5:$E$5,0)) -> 674602 | H44: =$F44*INDEX('Ownerhsip %'!$C$6:$E$20,MATCH($B44,'Ownerhsip %'!$B$6:$B$20,0),MATCH(H$11,'Ownerhsip %'!$C$5:$E$5,0)) -> 0 | I44: =$F44*INDEX('Ownerhsip %'!$C$6:$E$20,MATCH($B44,'Ownerhsip %'!$B$6:$B$20,0),MATCH(I$11,'Ownerhsip %'!$C$5:$E$5,0)) -> 0
... B47: Investment 15 | C47: =INDEX('Ownerhsip %'!$C$6:$E$20,MATCH('Quarterly Input Tab'!$B47,'Ownerhsip %'!$B$6:$B$20,0),MATCH('Quarterly Input Tab'!C$11,'Ownerhsip %'!$C$5:$E$5,0)) -> 0 | D47: =INDEX('Ownerhsip %'!$C$6:$E$20,MATCH('Quarterly Input Tab'!$B47,'Ownerhsip %'!$B$6:$B$20,0),MATCH('Quarterly Input Tab'!D$11,'Ownerhsip %'!$C$5:$E$5,0)) -> 0 | E47: =INDEX('Ownerhsip %'!$C$6:$E$20,MATCH('Quarterly Input Tab'!$B47,'Ownerhsip %'!$B$6:$B$20,0),MATCH('Quarterly Input Tab'!E$11,'Ownerhsip %'!$C$5:$E$5,0)) -> 1 | F47: 3097469 | G47: =$F47*INDEX('Ownerhsip %'!$C$6:$E$20,MATCH($B47,'Ownerhsip %'!$B$6:$B$20,0),MATCH(G$11,'Ownerhsip %'!$C$5:$E$5,0)) -> 0 | H47: =$F47*INDEX('Ownerhsip %'!$C$6:$E$20,MATCH($B47,'Ownerhsip %'!$B$6:$B$20,0),MATCH(H$11,'Ownerhsip %'!$C$5:$E$5,0)) -> 0 | I47: =$F47*INDEX('Ownerhsip %'!$C$6:$E$20,MATCH($B47,'Ownerhsip %'!$B$6:$B$20,0),MATCH(I$11,'Ownerhsip %'!$C$5:$E$5,0)) -> 3097469

Sheet Normal user can see this>

Sheet Ownerhsip %
B2: only updated my admin on the basis of the agreement
C4: Funds >>
B5: Investment Name | C5: Fund 1 | D5: Fund 2 | E5: Fund 3
B6: Investment 1 | C6: 0.5 | D6: 0.5 | E6: 0
B7: Investment 2 | C7: 1
B8: Investment 3 | C8: 1
B9: Investment 4 | D9: 0.75 | E9: 0.25
B10: Investment 5 | E10: 1
B11: Investment 6 | E11: 1
B12: Investment 7 | D12: 1
B13: Investment 8 | D13: 1
B14: Investment 9 | D14: 1
B15: Investment 10 | D15: 1
B16: Investment 11 | C16: 0.5 | E16: 0.5
B17: Investment 12 | C17: 1
B18: Investment 13 | C18: 1
B19: Investment 14 | C19: 1
B20: Investment 15 | E20: 1

Sheet Cashflows Input Tab
A2: whatever I put as a new cashflow it should be having a single id to identification
B3: 1. Dummy cashflow input table
B4: deal name | C4: fund name | D4: Transaction type | E4: cash date | F4: deal currency | G4: deal amt | H4: fund currency | I4: fund amt
B5: Investment 1 | C5: Fund 1 | D5: Contribution | E5: 44652 | F5: USD | G5: 400000 | H5: USD | I5: 400000 | L5: << to replicate this type to table for user input
B6: Investment 1 | C6: Fund 2 | D6: Contribution | E6: 44652 | F6: USD | G6: 400000 | H6: USD | I6: 400000
A8: Need these button >> | B8: Submit button (it submit all the data in input tbale above to the consolidated data)
B11: 2. cashflow table (all the inputs are consolidated here)
A12: cashflow id (system generated) | B12: deal name | C12: fund name | D12: Transaction type | E12: cash date | F12: deal currency | G12: deal amt | H12: fund currency | I12: fund amt
A13: Sys - 000001 | B13: Investment 1 | C13: Fund 1 | D13: Contribution | E13: 44652 | F13: USD | G13: 400000 | H13: USD | I13: 400000 | K13: < this is a consolidated table for all the input we submit in the above table
A14: Sys - 000002 | B14: Investment 1 | C14: Fund 2 | D14: Contribution | E14: 44652 | F14: USD | G14: 400000 | H14: USD | I14: 400000 | K14: << This table is the true source for all the materials where we need the cashflows
A17: Need this button >> | B17: Delete row button( enables the delete checkbox column at the end which when ticked makes those row eligible to be deleted from the system, thes helps us update the table to the most accurate data.)

Sheet Working Logic Tabs >>

Sheet NAV Walk tab
E4: Hypothetical for now due to low data | M4: level 2 MOIC | N4: Level 3 IRR
C5: Deal name | D5: fund name | E5: beginning NAV | F5: contribution | G5: Disposition | H5: current income(plus to have cashflow impact) | I5: cashflow adjusted NAV | J5: current inomce(-ive to remove the valuation impact) | K5: write up/down(the balancing figure/ plugin figure) | L5: ending NAV | M5: MOIC | N5: IRR
A6: example | C6: Investment 1 | D6: Fund 1 | E6: 425000 | F6: 25000 | G6: 0 | H6: 5000 | I6: =SUM(E6:H6) -> 455000 | J6: =-H6 -> -5000 | K6: =L6-SUM(I6:J6) -> 50000 | L6: =INDEX('Quarterly Input Tab'!$G:$I,MATCH('NAV Walk tab'!$C6,'Quarterly Input Tab'!$B:$B,0),MATCH('NAV Walk tab'!$D6,'Quarterly Input Tab'!$G$11:$I$11,0)) -> 500000 | M6: ='Returns Calculations'!D9 -> 1.1882353 | N6: ='Returns Calculations'!D10 -> 0.068167768
A7: example | C7: Investment 1 | D7: Fund 2 | E7: 425000 | F7: 25000 | G7: 0 | H7: 5000 | I7: =SUM(E7:H7) -> 455000 | J7: =-H7 -> -5000 | K7: =L7-SUM(I7:J7) -> 50000 | L7: =INDEX('Quarterly Input Tab'!$G:$I,MATCH('NAV Walk tab'!$C7,'Quarterly Input Tab'!$B:$B,0),MATCH('NAV Walk tab'!$D7,'Quarterly Input Tab'!$G$11:$I$11,0)) -> 500000 | M7: ='Returns Calculations'!E9 -> 1.1882353 | N7: ='Returns Calculations'!E10 -> 0.068167768

Sheet Returns Calculations
C3: For Investment 1 its first investment was in 01/04/2022
D5: example for ITD IRR calc
D7: Fund 1 | E7: Fund 2
D8: Investment 1 | E8: Investment 1
C9: MOIC | D9: =-SUMIFS(D$12:D$1020,D12:D1020,">0")/SUMIFS(D$12:D$1020,D12:D1020,"<0") -> 1.1882353 | E9: =-SUMIFS(E$12:E$1020,E12:E1020,">0")/SUMIFS(E$12:E$1020,E12:E1020,"<0") -> 1.1882353
C10: XIRR | D10: =XIRR(D12:D$1020,$B$12:$B$1020,0.01) -> 0.068167768 | E10: =XIRR(E12:E$1020,$B$12:$B$1020,0.01) -> 0.068167768
B12: 45017 | D12: =-'Cashflows Input Tab'!I13 -> -400000 | E12: =-'Cashflows Input Tab'!I14 -> -400000
B13: =B12+1 -> 45018 | D13: 0 | E13: 0
B14: =B13+1 -> 45019 | D14: 0 | E14: 0
B15: =B14+1 -> 45020 | D15: 0 | E15: 0
B16: =B15+1 -> 45021 | D16: 0 | E16: 0
B17: =B16+1 -> 45022 | D17: 0 | E17: 0
B18: =B17+1 -> 45023 | D18: 0 | E18: 0
B19: =B18+1 -> 45024 | D19: 0 | E19: 0
B20: =B19+1 -> 45025 | D20: 0 | E20: 0
B21: =B20+1 -> 45026 | D21: 0 | E21: 0
B22: =B21+1 -> 45027 | D22: 0 | E22: 0
B23: =B22+1 -> 45028 | D23: 0 | E23: 0
B24: =B23+1 -> 45029 | D24: 0 | E24: 0
... B934: =B933+1 -> 45939 | D934: 0 | E934: 0
B935: =B934+1 -> 45940 | D935: =-'NAV Walk tab'!F6 -> -25000 | E935: =-'NAV Walk tab'!F7 -> -25000 | F935: << lets say these CFs happened here, will have better consolidated data later
B936: =B935+1 -> 45941 | D936: 0 | E936: 0
B937: =B936+1 -> 45942 | D937: 0 | E937: 0
B938: =B937+1 -> 45943 | D938: 0 | E938: 0
B939: =B938+1 -> 45944 | D939: 0 | E939: 0
B940: =B939+1 -> 45945 | D940: 0 | E940: 0
B941: =B940+1 -> 45946 | D941: 0 | E941: 0
B942: =B941+1 -> 45947 | D942: 0 | E942: 0
B943: =B942+1 -> 45948 | D943: 0 | E943: 0
B944: =B943+1 -> 45949 | D944: 0 | E944: 0
B945: =B944+1 -> 45950 | D945: 0 | E945: 0
B946: =B945+1 -> 45951 | D946: 0 | E946: 0
B947: =B946+1 -> 45952 | D947: 0 | E947: 0
... B1000: =B999+1 -> 46005 | D1000: 0 | E1000: 0
B1001: =B1000+1 -> 46006 | D1001: ='NAV Walk tab'!H6 -> 5000 | E1001: ='NAV Walk tab'!H7 -> 5000 | F1001: << lets say these CFs happened here, will have better consolidated data later
B1002: =B1001+1 -> 46007 | D1002: 0 | E1002: 0
B1003: =B1002+1 -> 46008 | D1003: 0 | E1003: 0
B1004: =B1003+1 -> 46009 | D1004: 0 | E1004: 0
B1005: =B1004+1 -> 46010 | D1005: 0 | E1005: 0
B1006: =B1005+1 -> 46011 | D1006: 0 | E1006: 0
...
